Workbook

Sheet Executive Summary
B2: PROJECT ALPHA — Client Portal Modernization
B3: Project Proposal & Status Report
B5: PROJECT DETAILS | G5: KEY METRICS
B6: Client | C6: Northwind Financial Group | G6: Total budget (incl. contingency) | I6: ='Cost Breakdown'!G24 -> 796345
B7: Executive sponsor | C7: Dana Whitfield, CFO | G7: Spent to date | I7: ='Cost Breakdown'!H24 -> 370100
B8: Project manager | C8: Jordan Lee | G8: Remaining budget | I8: =I6-I7 -> 426245
B9: Proposal date | C9: 46310 | G9: % of budget used | I9: =IF(I6=0,0,I7/I6) -> 0.46474832
B10: Status date | C10: 46477 | G10: Overall % complete | I10: ='Timeline & Milestones'!I14 -> 0.46868009
B11: Planned start | C11: ='Timeline & Milestones'!$E$7 -> 46328 | G11: Milestones complete | I11: =COUNTIF('Timeline & Milestones'!F19:F25,"Complete")&" of "&COUNTA('Timeline & Milestones'!C19:C25) -> 2 of 7
B12: Planned finish | C12: ='Timeline & Milestones'!$F$13 -> 46598 | G12: Overdue phases | I12: =COUNTIF('Timeline & Milestones'!J7:J13,"Overdue") -> 1
B13: Total duration | C13: =DATE(YEAR('Timeline & Milestones'!$F$13),MONTH('Timeline & Milestones'!$F$13),DAY('Timeline & Milestones'!$F$13))-DATE(YEAR('Timeline & Milestones'!$E$7),MONTH('Timeline & Milestones'!$E$7),DAY('Timeline & Milestones'!$E$7))+1 -> 271 | G13: Project health | I13: =IF(OR(I12>1,I9-I10>0.15),"Off Track",IF(OR(I12=1,I9-I10>0.05),"At Risk","On Track")) -> At Risk
B15: SCOPE & OBJECTIVES
B16: 1. | C16: Replace the legacy client portal with a modern web app that lets clients view, edit, and approve financial documents in the browser.
B17: 2. | C17: Keep sensitive client files inside the application — no download-edit-reupload loop and no third-party processing.
B18: 3. | C18: Cut average approval turnaround from 6 business days to 2 by Q3 2027.
B19: 4. | C19: Launch to 1,200 client users with full training and a 2-week hypercare period.
B21: BUDGET SNAPSHOT BY CATEGORY | G21: APPROVALS
B22: Category | C22: Budget ($) | D22: Actual ($) | E22: % Spent | G22: Role | H22: Name | I22: Decision
B23: ='Cost Breakdown'!B29 -> Labor | C23: ='Cost Breakdown'!C29 -> 584600 | D23: ='Cost Breakdown'!D29 -> 294850 | E23: =IF(C23=0,0,D23/C23) -> 0.50436196 | G23: Executive sponsor | H23: Dana Whitfield | I23: Approved
B24: ='Cost Breakdown'!B30 -> Software & Licensing | C24: ='Cost Breakdown'!C30 -> 77850 | D24: ='Cost Breakdown'!D30 -> 63250 | E24: =IF(C24=0,0,D24/C24) -> 0.81245986 | G24: IT security | H24: Kim Nguyen | I24: Approved
B25: ='Cost Breakdown'!B31 -> Infrastructure | C25: ='Cost Breakdown'!C31 -> 18000 | D25: ='Cost Breakdown'!D31 -> 12000 | E25: =IF(C25=0,0,D25/C25) -> 0.66666667 | G25: Finance | H25: Priya Shah | I25: Pending
B26: ='Cost Breakdown'!B32 -> Training & Change | C26: ='Cost Breakdown'!C32 -> 18000 | D26: ='Cost Breakdown'!D32 -> 0 | E26: =IF(C26=0,0,D26/C26) -> 0
B27: ='Cost Breakdown'!B33 -> Professional Services | C27: ='Cost Breakdown'!C33 -> 25500 | D27: ='Cost Breakdown'!D33 -> 0 | E27: =IF(C27=0,0,D27/C27) -> 0
B30: Fictional sample project created for product demo videos. Names, figures, and dates are illustrative.
B31: Color key: blue text = input · black = formula · green = linked from another sheet · yellow fill = key assumption

Sheet Cost Breakdown
B2: Cost Breakdown
B3: Project Alpha — line-item budget, actuals to date, and monthly spend plan
B5: Contingency rate | C5: 0.1 | E5: Status date | F5: ='Executive Summary'!$C$10 -> 46477
B7: Category | C7: Line Item | D7: Qty | E7: Unit | F7: Unit Cost ($) | G7: Budget ($) | H7: Actual to Date ($) | I7: Variance ($) | J7: % Spent
B8: Labor | C8: Project management | D8: 9 | E8: month | F8: 14000 | G8: =D8*F8 -> 126000 | H8: 70000 | I8: =G8-H8 -> 56000 | J8: =IF(G8=0,0,H8/G8) -> 0.55555556
B9: Labor | C9: UX/UI design | D9: 10 | E9: week | F9: 6500 | G9: =D9*F9 -> 65000 | H9: 68250 | I9: =G9-H9 -> -3250 | J9: =IF(G9=0,0,H9/G9) -> 1.05
B10: Labor | C10: Front-end development | D10: 24 | E10: week | F10: 7200 | G10: =D10*F10 -> 172800 | H10: 86400 | I10: =G10-H10 -> 86400 | J10: =IF(G10=0,0,H10/G10) -> 0.5
B11: Labor | C11: Back-end & integrations | D11: 20 | E11: week | F11: 7800 | G11: =D11*F11 -> 156000 | H11: 70200 | I11: =G11-H11 -> 85800 | J11: =IF(G11=0,0,H11/G11) -> 0.45
B12: Labor | C12: QA & testing | D12: 12 | E12: week | F12: 5400 | G12: =D12*F12 -> 64800 | H12: 0 | I12: =G12-H12 -> 64800 | J12: =IF(G12=0,0,H12/G12) -> 0
B13: Software & Licensing | C13: Document SDK license | D13: 1 | E13: year | F13: 45000 | G13: =D13*F13 -> 45000 | H13: 45000 | I13: =G13-H13 -> 0 | J13: =IF(G13=0,0,H13/G13) -> 1
B14: Software & Licensing | C14: Cloud hosting | D14: 9 | E14: month | F14: 3200 | G14: =D14*F14 -> 28800 | H14: 16000 | I14: =G14-H14 -> 12800 | J14: =IF(G14=0,0,H14/G14) -> 0.55555556
B15: Software & Licensing | C15: Monitoring & logging | D15: 9 | E15: month | F15: 450 | G15: =D15*F15 -> 4050 | H15: 2250 | I15: =G15-H15 -> 1800 | J15: =IF(G15=0,0,H15/G15) -> 0.55555556
B16: Infrastructure | C16: Staging environment | D16: 1 | E16: lot | F16: 12000 | G16: =D16*F16 -> 12000 | H16: 12000 | I16: =G16-H16 -> 0 | J16: =IF(G16=0,0,H16/G16) -> 1
B17: Infrastructure | C17: Load testing service | D17: 1 | E17: lot | F17: 6000 | G17: =D17*F17 -> 6000 | H17: 0 | I17: =G17-H17 -> 6000 | J17: =IF(G17=0,0,H17/G17) -> 0
B18: Training & Change | C18: Admin training sessions | D18: 4 | E18: session | F18: 2500 | G18: =D18*F18 -> 10000 | H18: 0 | I18: =G18-H18 -> 10000 | J18: =IF(G18=0,0,H18/G18) -> 0
B19: Training & Change | C19: User guides & videos | D19: 1 | E19: lot | F19: 8000 | G19: =D19*F19 -> 8000 | H19: 0 | I19: =G19-H19 -> 8000 | J19: =IF(G19=0,0,H19/G19) -> 0
... B21: Professional Services | C21: Accessibility review | D21: 1 | E21: lot | F21: 7500 | G21: =D21*F21 -> 7500 | H21: 0 | I21: =G21-H21 -> 7500 | J21: =IF(G21=0,0,H21/G21) -> 0
B22: Subtotal | G22: =SUM(G8:G21) -> 723950 | H22: =SUM(H8:H21) -> 370100 | I22: =G22-H22 -> 353850 | J22: =IF(G22=0,0,H22/G22) -> 0.51122315
B23: Contingency | G23: =G22*'Cost Breakdown'!$C$5 -> 72395 | I23: =G23-H23 -> 72395
B24: TOTAL PROJECT BUDGET | G24: =G22+G23 -> 796345 | H24: =H22+H23 -> 370100 | I24: =G24-H24 -> 426245 | J24: =IF(G24=0,0,H24/G24) -> 0.46474832
B27: BUDGET BY CATEGORY
B28: Category | C28: Budget ($) | D28: Actual ($) | E28: Variance ($) | F28: % Spent
B29: Labor | C29: =SUMIFS($G$8:$G$21,$B$8:$B$21,B29) -> 584600 | D29: =SUMIFS($H$8:$H$21,$B$8:$B$21,B29) -> 294850 | E29: =C29-D29 -> 289750 | F29: =IF(C29=0,0,D29/C29) -> 0.50436196
B30: Software & Licensing | C30: =SUMIFS($G$8:$G$21,$B$8:$B$21,B30) -> 77850 | D30: =SUMIFS($H$8:$H$21,$B$8:$B$21,B30) -> 63250 | E30: =C30-D30 -> 14600 | F30: =IF(C30=0,0,D30/C30) -> 0.81245986
B31: Infrastructure | C31: =SUMIFS($G$8:$G$21,$B$8:$B$21,B31) -> 18000 | D31: =SUMIFS($H$8:$H$21,$B$8:$B$21,B31) -> 12000 | E31: =C31-D31 -> 6000 | F31: =IF(C31=0,0,D31/C31) -> 0.66666667
B32: Training & Change | C32: =SUMIFS($G$8:$G$21,$B$8:$B$21,B32) -> 18000 | D32: =SUMIFS($H$8:$H$21,$B$8:$B$21,B32) -> 0 | E32: =C32-D32 -> 18000 | F32: =IF(C32=0,0,D32/C32) -> 0
B33: Professional Services | C33: =SUMIFS($G$8:$G$21,$B$8:$B$21,B33) -> 25500 | D33: =SUMIFS($H$8:$H$21,$B$8:$B$21,B33) -> 0 | E33: =C33-D33 -> 25500 | F33: =IF(C33=0,0,D33/C33) -> 0
B34: Total (before contingency) | C34: =SUM(C29:C33) -> 723950 | D34: =SUM(D29:D33) -> 370100 | E34: =C34-D34 -> 353850 | F34: =IF(C34=0,0,D34/C34) -> 0.51122315
B37: MONTHLY SPEND PLAN
B38: Month | C38: Phasing % | D38: Planned ($) | E38: Actual ($) | F38: Cum. Planned ($) | G38: Cum. Actual ($)
B39: 46327 | C39: 0.06 | D39: =$G$22*C39 -> 43437 | E39: 38500 | F39: =D39 -> 43437 | G39: =E39 -> 38500
B40: 46357 | C40: 0.09 | D40: =$G$22*C40 -> 65155.5 | E40: 61200 | F40: =F39+D40 -> 108592.5 | G40: =G39+E40 -> 99700
B41: 46388 | C41: 0.14 | D41: =$G$22*C41 -> 101353 | E41: 102400 | F41: =F40+D41 -> 209945.5 | G41: =G40+E41 -> 202100
B42: 46419 | C42: 0.13 | D42: =$G$22*C42 -> 94113.5 | E42: 79300 | F42: =F41+D42 -> 304059 | G42: =G41+E42 -> 281400
B43: 46447 | C43: 0.13 | D43: =$G$22*C43 -> 94113.5 | E43: 88700 | F43: =F42+D43 -> 398172.5 | G43: =G42+E43 -> 370100
B44: 46478 | C44: 0.14 | D44: =$G$22*C44 -> 101353 | F44: =F43+D44 -> 499525.5
B45: 46508 | C45: 0.13 | D45: =$G$22*C45 -> 94113.5 | F45: =F44+D45 -> 593639
B46: 46539 | C46: 0.11 | D46: =$G$22*C46 -> 79634.5 | F46: =F45+D46 -> 673273.5
B47: 46569 | C47: 0.07 | D47: =$G$22*C47 -> 50676.5 | F47: =F46+D47 -> 723950
B48: Total | C48: =SUM(C39:C47) -> 1 | D48: =SUM(D39:D47) -> 723950 | E48: =SUM(E39:E47) -> 370100
...

Sheet Timeline & Milestones
B2: Timeline & Milestones
B3: Project Alpha — phase schedule, progress, and key milestones
B4: Status date | D4: ='Executive Summary'!$C$10 -> 46477
B6: # | C6: Phase | D6: Owner | E6: Start | F6: End | G6: Duration (days) | H6: Working Days | I6: % Complete | J6: Status
B7: 1 | C7: Discovery & Requirements | D7: J. Lee | E7: 46328 | F7: 46353 | G7: =DATE(YEAR(F7),MONTH(F7),DAY(F7))-DATE(YEAR(E7),MONTH(E7),DAY(E7))+1 -> 26 | H7: =NETWORKDAYS(DATE(YEAR(E7),MONTH(E7),DAY(E7)),DATE(YEAR(F7),MONTH(F7),DAY(F7))) -> 20 | I7: 1 | J7: =IF(I7>=1,"Complete",IF(DATE(YEAR('Executive Summary'!$C$10),MONTH('Executive Summary'!$C$10),DAY('Executive Summary'!$C$10))>DATE(YEAR(F7),MONTH(F7),DAY(F7)),"Overdue",IF(DATE(YEAR('Executive Summary'!$C$10),MONTH('Executive Summary'!$C$10),DAY('Executive Summary'!$C$10))>=DATE(YEAR(E7),MONTH(E7),DAY(E7)),"In Progress","Not Started"))) -> Complete
B8: 2 | C8: UX/UI Design | D8: M. Okafor | E8: 46356 | F8: 46409 | G8: =DATE(YEAR(F8),MONTH(F8),DAY(F8))-DATE(YEAR(E8),MONTH(E8),DAY(E8))+1 -> 54 | H8: =NETWORKDAYS(DATE(YEAR(E8),MONTH(E8),DAY(E8)),DATE(YEAR(F8),MONTH(F8),DAY(F8))) -> 40 | I8: 0.95 | J8: =IF(I8>=1,"Complete",IF(DATE(YEAR('Executive Summary'!$C$10),MONTH('Executive Summary'!$C$10),DAY('Executive Summary'!$C$10))>DATE(YEAR(F8),MONTH(F8),DAY(F8)),"Overdue",IF(DATE(YEAR('Executive Summary'!$C$10),MONTH('Executive Summary'!$C$10),DAY('Executive Summary'!$C$10))>=DATE(YEAR(E8),MONTH(E8),DAY(E8)),"In Progress","Not Started"))) -> Overdue
B9: 3 | C9: Front-end Build | D9: S. Patel | E9: 46391 | F9: 46507 | G9: =DATE(YEAR(F9),MONTH(F9),DAY(F9))-DATE(YEAR(E9),MONTH(E9),DAY(E9))+1 -> 117 | H9: =NETWORKDAYS(DATE(YEAR(E9),MONTH(E9),DAY(E9)),DATE(YEAR(F9),MONTH(F9),DAY(F9))) -> 85 | I9: 0.6 | J9: =IF(I9>=1,"Complete",IF(DATE(YEAR('Executive Summary'!$C$10),MONTH('Executive Summary'!$C$10),DAY('Executive Summary'!$C$10))>DATE(YEAR(F9),MONTH(F9),DAY(F9)),"Overdue",IF(DATE(YEAR('Executive Summary'!$C$10),MONTH('Executive Summary'!$C$10),DAY('Executive Summary'!$C$10))>=DATE(YEAR(E9),MONTH(E9),DAY(E9)),"In Progress","Not Started"))) -> In Progress
B10: 4 | C10: Back-end & Integrations | D10: R. Alvarez | E10: 46398 | F10: 46521 | G10: =DATE(YEAR(F10),MONTH(F10),DAY(F10))-DATE(YEAR(E10),MONTH(E10),DAY(E10))+1 -> 124 | H10: =NETWORKDAYS(DATE(YEAR(E10),MONTH(E10),DAY(E10)),DATE(YEAR(F10),MONTH(F10),DAY(F10))) -> 90 | I10: 0.5 | J10: =IF(I10>=1,"Complete",IF(DATE(YEAR('Executive Summary'!$C$10),MONTH('Executive Summary'!$C$10),DAY('Executive Summary'!$C$10))>DATE(YEAR(F10),MONTH(F10),DAY(F10)),"Overdue",IF(DATE(YEAR('Executive Summary'!$C$10),MONTH('Executive Summary'!$C$10),DAY('Executive Summary'!$C$10))>=DATE(YEAR(E10),MONTH(E10),DAY(E10)),"In Progress","Not Started"))) -> In Progress
B11: 5 | C11: QA & Security | D11: K. Nguyen | E11: 46482 | F11: 46549 | G11: =DATE(YEAR(F11),MONTH(F11),DAY(F11))-DATE(YEAR(E11),MONTH(E11),DAY(E11))+1 -> 68 | H11: =NETWORKDAYS(DATE(YEAR(E11),MONTH(E11),DAY(E11)),DATE(YEAR(F11),MONTH(F11),DAY(F11))) -> 50 | I11: 0 | J11: =IF(I11>=1,"Complete",IF(DATE(YEAR('Executive Summary'!$C$10),MONTH('Executive Summary'!$C$10),DAY('Executive Summary'!$C$10))>DATE(YEAR(F11),MONTH(F11),DAY(F11)),"Overdue",IF(DATE(YEAR('Executive Summary'!$C$10),MONTH('Executive Summary'!$C$10),DAY('Executive Summary'!$C$10))>=DATE(YEAR(E11),MONTH(E11),DAY(E11)),"In Progress","Not Started"))) -> Not Started
B12: 6 | C12: Training & Rollout | D12: D. Whitfield | E12: 46539 | F12: 46584 | G12: =DATE(YEAR(F12),MONTH(F12),DAY(F12))-DATE(YEAR(E12),MONTH(E12),DAY(E12))+1 -> 46 | H12: =NETWORKDAYS(DATE(YEAR(E12),MONTH(E12),DAY(E12)),DATE(YEAR(F12),MONTH(F12),DAY(F12))) -> 34 | I12: 0 | J12: =IF(I12>=1,"Complete",IF(DATE(YEAR('Executive Summary'!$C$10),MONTH('Executive Summary'!$C$10),DAY('Executive Summary'!$C$10))>DATE(YEAR(F12),MONTH(F12),DAY(F12)),"Overdue",IF(DATE(YEAR('Executive Summary'!$C$10),MONTH('Executive Summary'!$C$10),DAY('Executive Summary'!$C$10))>=DATE(YEAR(E12),MONTH(E12),DAY(E12)),"In Progress","Not Started"))) -> Not Started
B13: 7 | C13: Hypercare & Close | D13: J. Lee | E13: 46587 | F13: 46598 | G13: =DATE(YEAR(F13),MONTH(F13),DAY(F13))-DATE(YEAR(E13),MONTH(E13),DAY(E13))+1 -> 12 | H13: =NETWORKDAYS(DATE(YEAR(E13),MONTH(E13),DAY(E13)),DATE(YEAR(F13),MONTH(F13),DAY(F13))) -> 10 | I13: 0 | J13: =IF(I13>=1,"Complete",IF(DATE(YEAR('Executive Summary'!$C$10),MONTH('Executive Summary'!$C$10),DAY('Executive Summary'!$C$10))>DATE(YEAR(F13),MONTH(F13),DAY(F13)),"Overdue",IF(DATE(YEAR('Executive Summary'!$C$10),MONTH('Executive Summary'!$C$10),DAY('Executive Summary'!$C$10))>=DATE(YEAR(E13),MONTH(E13),DAY(E13)),"In Progress","Not Started"))) -> Not Started
B14: Overall % complete (weighted by duration) | I14: =SUMPRODUCT(G7:G13,I7:I13)/SUM(G7:G13) -> 0.46868009
B17: KEY MILESTONES
B18: # | C18: Milestone | D18: Phase | E18: Due Date | F18: Status | G18: Days to Due
B19: 1 | C19: Requirements sign-off | D19: Discovery & Requirements | E19: 46353 | F19: Complete | G19: =IF(F19="Complete",0,DATE(YEAR(E19),MONTH(E19),DAY(E19))-DATE(YEAR('Executive Summary'!$C$10),MONTH('Executive Summary'!$C$10),DAY('Executive Summary'!$C$10))) -> 0
B20: 2 | C20: Design approval | D20: UX/UI Design | E20: 46409 | F20: Complete | G20: =IF(F20="Complete",0,DATE(YEAR(E20),MONTH(E20),DAY(E20))-DATE(YEAR('Executive Summary'!$C$10),MONTH('Executive Summary'!$C$10),DAY('Executive Summary'!$C$10))) -> 0
B21: 3 | C21: Beta release | D21: Front-end Build | E21: 46507 | F21: On Track | G21: =IF(F21="Complete",0,DATE(YEAR(E21),MONTH(E21),DAY(E21))-DATE(YEAR('Executive Summary'!$C$10),MONTH('Executive Summary'!$C$10),DAY('Executive Summary'!$C$10))) -> 30
B22: 4 | C22: Integrations complete | D22: Back-end & Integrations | E22: 46521 | F22: At Risk | G22: =IF(F22="Complete",0,DATE(YEAR(E22),MONTH(E22),DAY(E22))-DATE(YEAR('Executive Summary'!$C$10),MONTH('Executive Summary'!$C$10),DAY('Executive Summary'!$C$10))) -> 44
B23: 5 | C23: Security audit passed | D23: QA & Security | E23: 46549 | F23: Not Started | G23: =IF(F23="Complete",0,DATE(YEAR(E23),MONTH(E23),DAY(E23))-DATE(YEAR('Executive Summary'!$C$10),MONTH('Executive Summary'!$C$10),DAY('Executive Summary'!$C$10))) -> 72
B24: 6 | C24: Go-live | D24: Training & Rollout | E24: 46584 | F24: Not Started | G24: =IF(F24="Complete",0,DATE(YEAR(E24),MONTH(E24),DAY(E24))-DATE(YEAR('Executive Summary'!$C$10),MONTH('Executive Summary'!$C$10),DAY('Executive Summary'!$C$10))) -> 107
B25: 7 | C25: Project close-out | D25: Hypercare & Close | E25: 46598 | F25: Not Started | G25: =IF(F25="Complete",0,DATE(YEAR(E25),MONTH(E25),DAY(E25))-DATE(YEAR('Executive Summary'!$C$10),MONTH('Executive Summary'!$C$10),DAY('Executive Summary'!$C$10))) -> 121

Sheet Budget Scenarios
B2: Budget Scenarios
B3: What-if planning: change the blue inputs and the chart updates instantly
B5: Scenario | C5: Labor adjustment | D5: Contingency | E5: Labor ($) | F5: Other costs ($) | G5: Contingency ($) | H5: Total ($)
B6: Lean | C6: -0.1 | D6: 0.05 | E6: ='Cost Breakdown'!$C$29*(1+C6) -> 526140 | F6: ='Cost Breakdown'!$C$34-'Cost Breakdown'!$C$29 -> 139350 | G6: =(E6+F6)*D6 -> 33274.5 | H6: =E6+F6+G6 -> 698764.5
B7: Base | C7: 0 | D7: 0.1 | E7: ='Cost Breakdown'!$C$29*(1+C7) -> 584600 | F7: ='Cost Breakdown'!$C$34-'Cost Breakdown'!$C$29 -> 139350 | G7: =(E7+F7)*D7 -> 72395 | H7: =E7+F7+G7 -> 796345
B8: Expanded | C8: 0.15 | D8: 0.15 | E8: ='Cost Breakdown'!$C$29*(1+C8) -> 672290 | F8: ='Cost Breakdown'!$C$34-'Cost Breakdown'!$C$29 -> 139350 | G8: =(E8+F8)*D8 -> 121746 | H8: =E8+F8+G8 -> 933386
B10: Labor and other costs come from the Cost Breakdown sheet. Nothing else in the workbook depends on this sheet.

Sheet Dashboard
B2: Project Alpha — Dashboard
B3: ="Status as of "&TEXT('Executive Summary'!$C$10,"mmmm d, yyyy")&" · Health: "&'Executive Summary'!I13 -> Status as of March 31, 2027 · Health: At Risk
B5: TOTAL BUDGET | F5: SPENT TO DATE | J5: OVERALL COMPLETE | N5: MILESTONES DONE
B6: ='Cost Breakdown'!G24 -> 796345 | F6: ='Cost Breakdown'!H24 -> 370100 | J6: ='Timeline & Milestones'!I14 -> 0.46868009 | N6: ='Executive Summary'!I11 -> 2 of 7
B8: ="incl. "&TEXT('Cost Breakdown'!$C$5,"0%")&" contingency" -> incl. 10% contingency | F8: =TEXT('Executive Summary'!I9,"0.0%")&" of budget" -> 46.5% of budget | J8: ='Executive Summary'!I12&" overdue phase(s)" -> 1 overdue phase(s) | N8: ="Next: "&IFERROR(VLOOKUP(COUNTIF('Timeline & Milestones'!F19:F25,"Complete")+1,'Timeline & Milestones'!B19:C25,2,FALSE()),"—") -> Next: Beta release
